Workbook

Sheet Воронка
A1: Воронка продаж, июнь — август 2026
A2: Все формулы считаются по листу «Сводная» (только строки с «В воронке» = 1). Дубли и переданные лиды учтены один раз.
A4: Общая воронка
A5: Этап | B5: Клиентов | C5: Конверсия из пред. этапа | D5: Конверсия из лида | E5: Потеряно на этапе
A6: Лиды | B6: =COUNTIFS(Сводная!$Y$2:$Y$436,1) -> 415 | D6: 1
A7: Контакт | B7: =COUNTIFS(Сводная!$Y$2:$Y$436,1,Сводная!$X$2:$X$436,1) -> 349 | C7: =IFERROR(B7/B6,0) -> 0.84096386 | D7: =IFERROR(B7/$B$6,0) -> 0.84096386 | E7: =B6-B7 -> 66
A8: Замер | B8: =COUNTIFS(Сводная!$Y$2:$Y$436,1,Сводная!$M$2:$M$436,1) -> 214 | C8: =IFERROR(B8/B7,0) -> 0.61318052 | D8: =IFERROR(B8/$B$6,0) -> 0.51566265 | E8: =B7-B8 -> 135
A9: КП | B9: =COUNTIFS(Сводная!$Y$2:$Y$436,1,Сводная!$O$2:$O$436,1) -> 190 | C9: =IFERROR(B9/B8,0) -> 0.88785047 | D9: =IFERROR(B9/$B$6,0) -> 0.45783133 | E9: =B8-B9 -> 24
A10: Оплата | B10: =COUNTIFS(Сводная!$Y$2:$Y$436,1,Сводная!$W$2:$W$436,1) -> 77 | C10: =IFERROR(B10/B9,0) -> 0.40526316 | D10: =IFERROR(B10/$B$6,0) -> 0.18554217 | E10: =B9-B10 -> 113
A12: Деньги, MDL
A13: Сумма выставленных КП | B13: =SUMIFS(Сводная!$S$2:$S$436,Сводная!$Y$2:$Y$436,1,Сводная!$O$2:$O$436,1) -> 6081438
A14: Оплачено | B14: =SUMIFS(Сводная!$S$2:$S$436,Сводная!$Y$2:$Y$436,1,Сводная!$W$2:$W$436,1) -> 2615100
A15: Средний чек оплаты | B15: =IFERROR(B14/B10,0) -> 33962.338
A16: В работе: КП отправлено, статус «Думает»/«Договор» | B16: =SUMIFS(Сводная!$S$2:$S$436,Сводная!$Y$2:$Y$436,1,Сводная!$O$2:$O$436,1,Сводная!$T$2:$T$436,"Думает")+SUMIFS(Сводная!$S$2:$S$436,Сводная!$Y$2:$Y$436,1,Сводная!$O$2:$O$436,1,Сводная!$T$2:$T$436,"Договор") -> 1174008
A17: Сделок в работе (шт.) | B17: =COUNTIFS(Сводная!$Y$2:$Y$436,1,Сводная!$O$2:$O$436,1,Сводная!$T$2:$T$436,"Думает")+COUNTIFS(Сводная!$Y$2:$Y$436,1,Сводная!$O$2:$O$436,1,Сводная!$T$2:$T$436,"Договор") -> 40
A18: Конверсия КП → оплата по деньгам | B18: =IFERROR(B14/B13,0) -> 0.43001343
A21: По менеджерам
B22: Лиды | C22: Контакт | D22: Замер | E22: КП | F22: Оплата | G22: Лид→Контакт | H22: Контакт→Замер | I22: Замер→КП | J22: КП→Оплата | K22: Лид→Оплата | L22: Оплачено, MDL | M22: Средний чек, MDL
A23: Наталья | B23: =COUNTIFS(Сводная!$Y$2:$Y$436,1,Сводная!$B$2:$B$436,"Наталья") -> 155 | C23: =COUNTIFS(Сводная!$Y$2:$Y$436,1,Сводная!$X$2:$X$436,1,Сводная!$B$2:$B$436,"Наталья") -> 127 | D23: =COUNTIFS(Сводная!$Y$2:$Y$436,1,Сводная!$M$2:$M$436,1,Сводная!$B$2:$B$436,"Наталья") -> 84 | E23: =COUNTIFS(Сводная!$Y$2:$Y$436,1,Сводная!$O$2:$O$436,1,Сводная!$B$2:$B$436,"Наталья") -> 75 | F23: =COUNTIFS(Сводная!$Y$2:$Y$436,1,Сводная!$W$2:$W$436,1,Сводная!$B$2:$B$436,"Наталья") -> 36 | G23: =IFERROR(C23/B23,0) -> 0.81935484 | H23: =IFERROR(D23/C23,0) -> 0.66141732 | I23: =IFERROR(E23/D23,0) -> 0.89285714 | J23: =IFERROR(F23/E23,0) -> 0.48 | K23: =IFERROR(F23/B23,0) -> 0.23225806 | L23: =SUMIFS(Сводная!$S$2:$S$436,Сводная!$Y$2:$Y$436,1,Сводная!$W$2:$W$436,1,Сводная!$B$2:$B$436,"Наталья") -> 1414800 | M23: =IFERROR(L23/F23,0) -> 39300
A24: Ион | B24: =COUNTIFS(Сводная!$Y$2:$Y$436,1,Сводная!$B$2:$B$436,"Ион") -> 132 | C24: =COUNTIFS(Сводная!$Y$2:$Y$436,1,Сводная!$X$2:$X$436,1,Сводная!$B$2:$B$436,"Ион") -> 102 | D24: =COUNTIFS(Сводная!$Y$2:$Y$436,1,Сводная!$M$2:$M$436,1,Сводная!$B$2:$B$436,"Ион") -> 64 | E24: =COUNTIFS(Сводная!$Y$2:$Y$436,1,Сводная!$O$2:$O$436,1,Сводная!$B$2:$B$436,"Ион") -> 55 | F24: =COUNTIFS(Сводная!$Y$2:$Y$436,1,Сводная!$W$2:$W$436,1,Сводная!$B$2:$B$436,"Ион") -> 18 | G24: =IFERROR(C24/B24,0) -> 0.77272727 | H24: =IFERROR(D24/C24,0) -> 0.62745098 | I24: =IFERROR(E24/D24,0) -> 0.859375 | J24: =IFERROR(F24/E24,0) -> 0.32727273 | K24: =IFERROR(F24/B24,0) -> 0.13636364 | L24: =SUMIFS(Сводная!$S$2:$S$436,Сводная!$Y$2:$Y$436,1,Сводная!$W$2:$W$436,1,Сводная!$B$2:$B$436,"Ион") -> 561300 | M24: =IFERROR(L24/F24,0) -> 31183.333
A25: Андрей | B25: =COUNTIFS(Сводная!$Y$2:$Y$436,1,Сводная!$B$2:$B$436,"Андрей") -> 128 | C25: =COUNTIFS(Сводная!$Y$2:$Y$436,1,Сводная!$X$2:$X$436,1,Сводная!$B$2:$B$436,"Андрей") -> 120 | D25: =COUNTIFS(Сводная!$Y$2:$Y$436,1,Сводная!$M$2:$M$436,1,Сводная!$B$2:$B$436,"Андрей") -> 66 | E25: =COUNTIFS(Сводная!$Y$2:$Y$436,1,Сводная!$O$2:$O$436,1,Сводная!$B$2:$B$436,"Андрей") -> 60 | F25: =COUNTIFS(Сводная!$Y$2:$Y$436,1,Сводная!$W$2:$W$436,1,Сводная!$B$2:$B$436,"Андрей") -> 23 | G25: =IFERROR(C25/B25,0) -> 0.9375 | H25: =IFERROR(D25/C25,0) -> 0.55 | I25: =IFERROR(E25/D25,0) -> 0.90909091 | J25: =IFERROR(F25/E25,0) -> 0.38333333 | K25: =IFERROR(F25/B25,0) -> 0.1796875 | L25: =SUMIFS(Сводная!$S$2:$S$436,Сводная!$Y$2:$Y$436,1,Сводная!$W$2:$W$436,1,Сводная!$B$2:$B$436,"Андрей") -> 639000 | M25: =IFERROR(L25/F25,0) -> 27782.609
A26: Итого | B26: =SUM(B23:B25) -> 415 | C26: =SUM(C23:C25) -> 349 | D26: =SUM(D23:D25) -> 214 | E26: =SUM(E23:E25) -> 190 | F26: =SUM(F23:F25) -> 77 | G26: =IFERROR(C26/B26,0) -> 0.84096386 | H26: =IFERROR(D26/C26,0) -> 0.61318052 | I26: =IFERROR(E26/D26,0) -> 0.88785047 | J26: =IFERROR(F26/E26,0) -> 0.40526316 | K26: =IFERROR(F26/B26,0) -> 0.18554217 | L26: =SUM(L23:L25) -> 2615100 | M26: =IFERROR(L26/F26,0) -> 33962.338
A28: По месяцу поступления лида (6 = июнь, 7 = июль, 8 = август)
B29: Лиды | C29: Контакт | D29: Замер | E29: КП | F29: Оплата | G29: Лид→Контакт | H29: Контакт→Замер | I29: Замер→КП | J29: КП→Оплата | K29: Лид→Оплата | L29: Оплачено, MDL | M29: Средний чек, MDL
A30: 6 | B30: =COUNTIFS(Сводная!$Y$2:$Y$436,1,Сводная!$E$2:$E$436,6) -> 158 | C30: =COUNTIFS(Сводная!$Y$2:$Y$436,1,Сводная!$X$2:$X$436,1,Сводная!$E$2:$E$436,6) -> 130 | D30: =COUNTIFS(Сводная!$Y$2:$Y$436,1,Сводная!$M$2:$M$436,1,Сводная!$E$2:$E$436,6) -> 80 | E30: =COUNTIFS(Сводная!$Y$2:$Y$436,1,Сводная!$O$2:$O$436,1,Сводная!$E$2:$E$436,6) -> 65 | F30: =COUNTIFS(Сводная!$Y$2:$Y$436,1,Сводная!$W$2:$W$436,1,Сводная!$E$2:$E$436,6) -> 27 | G30: =IFERROR(C30/B30,0) -> 0.82278481 | H30: =IFERROR(D30/C30,0) -> 0.61538462 | I30: =IFERROR(E30/D30,0) -> 0.8125 | J30: =IFERROR(F30/E30,0) -> 0.41538462 | K30: =IFERROR(F30/B30,0) -> 0.17088608 | L30: =SUMIFS(Сводная!$S$2:$S$436,Сводная!$Y$2:$Y$436,1,Сводная!$W$2:$W$436,1,Сводная!$E$2:$E$436,6) -> 953900 | M30: =IFERROR(L30/F30,0) -> 35329.63
A31: 7 | B31: =COUNTIFS(Сводная!$Y$2:$Y$436,1,Сводная!$E$2:$E$436,7) -> 160 | C31: =COUNTIFS(Сводная!$Y$2:$Y$436,1,Сводная!$X$2:$X$436,1,Сводная!$E$2:$E$436,7) -> 137 | D31: =COUNTIFS(Сводная!$Y$2:$Y$436,1,Сводная!$M$2:$M$436,1,Сводная!$E$2:$E$436,7) -> 86 | E31: =COUNTIFS(Сводная!$Y$2:$Y$436,1,Сводная!$O$2:$O$436,1,Сводная!$E$2:$E$436,7) -> 81 | F31: =COUNTIFS(Сводная!$Y$2:$Y$436,1,Сводная!$W$2:$W$436,1,Сводная!$E$2:$E$436,7) -> 34 | G31: =IFERROR(C31/B31,0) -> 0.85625 | H31: =IFERROR(D31/C31,0) -> 0.62773723 | I31: =IFERROR(E31/D31,0) -> 0.94186047 | J31: =IFERROR(F31/E31,0) -> 0.41975309 | K31: =IFERROR(F31/B31,0) -> 0.2125 | L31: =SUMIFS(Сводная!$S$2:$S$436,Сводная!$Y$2:$Y$436,1,Сводная!$W$2:$W$436,1,Сводная!$E$2:$E$436,7) -> 1200200 | M31: =IFERROR(L31/F31,0) -> 35300
A32: 8 | B32: =COUNTIFS(Сводная!$Y$2:$Y$436,1,Сводная!$E$2:$E$436,8) -> 97 | C32: =COUNTIFS(Сводная!$Y$2:$Y$436,1,Сводная!$X$2:$X$436,1,Сводная!$E$2:$E$436,8) -> 82 | D32: =COUNTIFS(Сводная!$Y$2:$Y$436,1,Сводная!$M$2:$M$436,1,Сводная!$E$2:$E$436,8) -> 48 | E32: =COUNTIFS(Сводная!$Y$2:$Y$436,1,Сводная!$O$2:$O$436,1,Сводная!$E$2:$E$436,8) -> 44 | F32: =COUNTIFS(Сводная!$Y$2:$Y$436,1,Сводная!$W$2:$W$436,1,Сводная!$E$2:$E$436,8) -> 16 | G32: =IFERROR(C32/B32,0) -> 0.84536082 | H32: =IFERROR(D32/C32,0) -> 0.58536585 | I32: =IFERROR(E32/D32,0) -> 0.91666667 | J32: =IFERROR(F32/E32,0) -> 0.36363636 | K32: =IFERROR(F32/B32,0) -> 0.16494845 | L32: =SUMIFS(Сводная!$S$2:$S$436,Сводная!$Y$2:$Y$436,1,Сводная!$W$2:$W$436,1,Сводная!$E$2:$E$436,8) -> 461000 | M32: =IFERROR(L32/F32,0) -> 28812.5
A33: Итого | B33: =SUM(B30:B32) -> 415 | C33: =SUM(C30:C32) -> 349 | D33: =SUM(D30:D32) -> 214 | E33: =SUM(E30:E32) -> 190 | F33: =SUM(F30:F32) -> 77 | G33: =IFERROR(C33/B33,0) -> 0.84096386 | H33: =IFERROR(D33/C33,0) -> 0.61318052 | I33: =IFERROR(E33/D33,0) -> 0.88785047 | J33: =IFERROR(F33/E33,0) -> 0.40526316 | K33: =IFERROR(F33/B33,0) -> 0.18554217 | L33: =SUM(L30:L32) -> 2615100 | M33: =IFERROR(L33/F33,0) -> 33962.338
A35: По источникам
B36: Лиды | C36: Контакт | D36: Замер | E36: КП | F36: Оплата | G36: Лид→Контакт | H36: Контакт→Замер | I36: Замер→КП | J36: КП→Оплата | K36: Лид→Оплата | L36: Оплачено, MDL | M36: Средний чек, MDL
A37: Instagram | B37: =COUNTIFS(Сводная!$Y$2:$Y$436,1,Сводная!$I$2:$I$436,"Instagram") -> 159 | C37: =COUNTIFS(Сводная!$Y$2:$Y$436,1,Сводная!$X$2:$X$436,1,Сводная!$I$2:$I$436,"Instagram") -> 130 | D37: =COUNTIFS(Сводная!$Y$2:$Y$436,1,Сводная!$M$2:$M$436,1,Сводная!$I$2:$I$436,"Instagram") -> 61 | E37: =COUNTIFS(Сводная!$Y$2:$Y$436,1,Сводная!$O$2:$O$436,1,Сводная!$I$2:$I$436,"Instagram") -> 52 | F37: =COUNTIFS(Сводная!$Y$2:$Y$436,1,Сводная!$W$2:$W$436,1,Сводная!$I$2:$I$436,"Instagram") -> 12 | G37: =IFERROR(C37/B37,0) -> 0.81761006 | H37: =IFERROR(D37/C37,0) -> 0.46923077 | I37: =IFERROR(E37/D37,0) -> 0.85245902 | J37: =IFERROR(F37/E37,0) -> 0.23076923 | K37: =IFERROR(F37/B37,0) -> 0.075471698 | L37: =SUMIFS(Сводная!$S$2:$S$436,Сводная!$Y$2:$Y$436,1,Сводная!$W$2:$W$436,1,Сводная!$I$2:$I$436,"Instagram") -> 273200 | M37: =IFERROR(L37/F37,0) -> 22766.667
A38: 999.md | B38: =COUNTIFS(Сводная!$Y$2:$Y$436,1,Сводная!$I$2:$I$436,"999.md") -> 95 | C38: =COUNTIFS(Сводная!$Y$2:$Y$436,1,Сводная!$X$2:$X$436,1,Сводная!$I$2:$I$436,"999.md") -> 76 | D38: =COUNTIFS(Сводная!$Y$2:$Y$436,1,Сводная!$M$2:$M$436,1,Сводная!$I$2:$I$436,"999.md") -> 46 | E38: =COUNTIFS(Сводная!$Y$2:$Y$436,1,Сводная!$O$2:$O$436,1,Сводная!$I$2:$I$436,"999.md") -> 44 | F38: =COUNTIFS(Сводная!$Y$2:$Y$436,1,Сводная!$W$2:$W$436,1,Сводная!$I$2:$I$436,"999.md") -> 20 | G38: =IFERROR(C38/B38,0) -> 0.8 | H38: =IFERROR(D38/C38,0) -> 0.60526316 | I38: =IFERROR(E38/D38,0) -> 0.95652174 | J38: =IFERROR(F38/E38,0) -> 0.45454545 | K38: =IFERROR(F38/B38,0) -> 0.21052632 | L38: =SUMIFS(Сводная!$S$2:$S$436,Сводная!$Y$2:$Y$436,1,Сводная!$W$2:$W$436,1,Сводная!$I$2:$I$436,"999.md") -> 581800 | M38: =IFERROR(L38/F38,0) -> 29090
A39: Рекомендация | B39: =COUNTIFS(Сводная!$Y$2:$Y$436,1,Сводная!$I$2:$I$436,"Рекомендация") -> 54 | C39: =COUNTIFS(Сводная!$Y$2:$Y$436,1,Сводная!$X$2:$X$436,1,Сводная!$I$2:$I$436,"Рекомендация") -> 52 | D39: =COUNTIFS(Сводная!$Y$2:$Y$436,1,Сводная!$M$2:$M$436,1,Сводная!$I$2:$I$436,"Рекомендация") -> 47 | E39: =COUNTIFS(Сводная!$Y$2:$Y$436,1,Сводная!$O$2:$O$436,1,Сводная!$I$2:$I$436,"Рекомендация") -> 42 | F39: =COUNTIFS(Сводная!$Y$2:$Y$436,1,Сводная!$W$2:$W$436,1,Сводная!$I$2:$I$436,"Рекомендация") -> 25 | G39: =IFERROR(C39/B39,0) -> 0.96296296 | H39: =IFERROR(D39/C39,0) -> 0.90384615 | I39: =IFERROR(E39/D39,0) -> 0.89361702 | J39: =IFERROR(F39/E39,0) -> 0.5952381 | K39: =IFERROR(F39/B39,0) -> 0.46296296 | L39: =SUMIFS(Сводная!$S$2:$S$436,Сводная!$Y$2:$Y$436,1,Сводная!$W$2:$W$436,1,Сводная!$I$2:$I$436,"Рекомендация") -> 1215500 | M39: =IFERROR(L39/F39,0) -> 48620
A40: Входящий звонок | B40: =COUNTIFS(Сводная!$Y$2:$Y$436,1,Сводная!$I$2:$I$436,"Входящий звонок") -> 49 | C40: =COUNTIFS(Сводная!$Y$2:$Y$436,1,Сводная!$X$2:$X$436,1,Сводная!$I$2:$I$436,"Входящий звонок") -> 44 | D40: =COUNTIFS(Сводная!$Y$2:$Y$436,1,Сводная!$M$2:$M$436,1,Сводная!$I$2:$I$436,"Входящий звонок") -> 37 | E40: =COUNTIFS(Сводная!$Y$2:$Y$436,1,Сводная!$O$2:$O$436,1,Сводная!$I$2:$I$436,"Входящий звонок") -> 32 | F40: =COUNTIFS(Сводная!$Y$2:$Y$436,1,Сводная!$W$2:$W$436,1,Сводная!$I$2:$I$436,"Входящий звонок") -> 16 | G40: =IFERROR(C40/B40,0) -> 0.89795918 | H40: =IFERROR(D40/C40,0) -> 0.84090909 | I40: =IFERROR(E40/D40,0) -> 0.86486486 | J40: =IFERROR(F40/E40,0) -> 0.5 | K40: =IFERROR(F40/B40,0) -> 0.32653061 | L40: =SUMIFS(Сводная!$S$2:$S$436,Сводная!$Y$2:$Y$436,1,Сводная!$W$2:$W$436,1,Сводная!$I$2:$I$436,"Входящий звонок") -> 431100 | M40: =IFERROR(L40/F40,0) -> 26943.75
A41: Facebook | B41: =COUNTIFS(Сводная!$Y$2:$Y$436,1,Сводная!$I$2:$I$436,"Facebook") -> 44 | C41: =COUNTIFS(Сводная!$Y$2:$Y$436,1,Сводная!$X$2:$X$436,1,Сводная!$I$2:$I$436,"Facebook") -> 37 | D41: =COUNTIFS(Сводная!$Y$2:$Y$436,1,Сводная!$M$2:$M$436,1,Сводная!$I$2:$I$436,"Facebook") -> 20 | E41: =COUNTIFS(Сводная!$Y$2:$Y$436,1,Сводная!$O$2:$O$436,1,Сводная!$I$2:$I$436,"Facebook") -> 19 | F41: =COUNTIFS(Сводная!$Y$2:$Y$436,1,Сводная!$W$2:$W$436,1,Сводная!$I$2:$I$436,"Facebook") -> 4 | G41: =IFERROR(C41/B41,0) -> 0.84090909 | H41: =IFERROR(D41/C41,0) -> 0.54054054 | I41: =IFERROR(E41/D41,0) -> 0.95 | J41: =IFERROR(F41/E41,0) -> 0.21052632 | K41: =IFERROR(F41/B41,0) -> 0.090909091 | L41: =SUMIFS(Сводная!$S$2:$S$436,Сводная!$Y$2:$Y$436,1,Сводная!$W$2:$W$436,1,Сводная!$I$2:$I$436,"Facebook") -> 113500 | M41: =IFERROR(L41/F41,0) -> 28375
A42: Не указан | B42: =COUNTIFS(Сводная!$Y$2:$Y$436,1,Сводная!$I$2:$I$436,"Не указан") -> 14 | C42: =COUNTIFS(Сводная!$Y$2:$Y$436,1,Сводная!$X$2:$X$436,1,Сводная!$I$2:$I$436,"Не указан") -> 10 | D42: =COUNTIFS(Сводная!$Y$2:$Y$436,1,Сводная!$M$2:$M$436,1,Сводная!$I$2:$I$436,"Не указан") -> 3 | E42: =COUNTIFS(Сводная!$Y$2:$Y$436,1,Сводная!$O$2:$O$436,1,Сводная!$I$2:$I$436,"Не указан") -> 1 | F42: =COUNTIFS(Сводная!$Y$2:$Y$436,1,Сводная!$W$2:$W$436,1,Сводная!$I$2:$I$436,"Не указан") -> 0 | G42: =IFERROR(C42/B42,0) -> 0.71428571 | H42: =IFERROR(D42/C42,0) -> 0.3 | I42: =IFERROR(E42/D42,0) -> 0.33333333 | J42: =IFERROR(F42/E42,0) -> 0 | K42: =IFERROR(F42/B42,0) -> 0 | L42: =SUMIFS(Сводная!$S$2:$S$436,Сводная!$Y$2:$Y$436,1,Сводная!$W$2:$W$436,1,Сводная!$I$2:$I$436,"Не указан") -> 0 | M42: =IFERROR(L42/F42,0) -> 0
A43: Итого | B43: =SUM(B37:B42) -> 415 | C43: =SUM(C37:C42) -> 349 | D43: =SUM(D37:D42) -> 214 | E43: =SUM(E37:E42) -> 190 | F43: =SUM(F37:F42) -> 77 | G43: =IFERROR(C43/B43,0) -> 0.84096386 | H43: =IFERROR(D43/C43,0) -> 0.61318052 | I43: =IFERROR(E43/D43,0) -> 0.88785047 | J43: =IFERROR(F43/E43,0) -> 0.40526316 | K43: =IFERROR(F43/B43,0) -> 0.18554217 | L43: =SUM(L37:L42) -> 2615100 | M43: =IFERROR(L43/F43,0) -> 33962.338
A45: Месяц — по дате поступления лида (когортный взгляд): оплата лида, пришедшего в июле, засчитывается июлю, даже если деньги пришли в августе.

Sheet Сводная
A1: № | B1: Менеджер | C1: Исходный лист, строка | D1: Дата лида | E1: Месяц | F1: Клиент | G1: Телефон (норм.) | H1: Город | I1: Источник | J1: Источник (как записано) | K1: Что | L1: Дата замера | M1: Замер | N1: Дата КП | O1: КП | P1: Сумма (как записано) | Q1: Сумма, число | R1: Валюта | S1: Сумма, MDL | T1: Статус | U1: Статус (как записано) | V1: Дата оплаты | W1: Оплата | X1: Контакт | Y1: В воронке | Z1: Почему исключено | AA1: Замечания к данным | AB1: Комментарий менеджера
A2: 1 | B2: Ион | C2: Ion, стр. 2 | D2: 46174 | E2: =MONTH(D2) -> 6 | F2: Людмила Волкова | G2: 60050594 | H2: Comrat | I2: Входящий звонок | J2: звонок | K2: fereastră 2 canate | L2: 46178 | M2: 1 | O2: 0 | S2: =IF(Q2="","",IF(R2="EUR",ROUND(Q2*Параметры!$B$3,0),Q2)) | T2: Отказ | U2: отказ | W2: =IF(T2="Оплачено",1,0) -> 0 | X2: =IF(OR(T2="Не дозвонились",Y2=0),0,1) -> 1 | Y2: 1 | AB2: ремонт перенесли, sună după ora 18
A3: 2 | B3: Андрей | C3: Андрей, стр. 5 | D3: 46174 | E3: =MONTH(D3) -> 6 | F3: Ольга Шевченко | G3: 60023030 | H3: КИШИНЕВ | I3: Facebook | J3: fb | K3: 3 окна + балкон | M3: 0 | O3: 0 | S3: =IF(Q3="","",IF(R3="EUR",ROUND(Q3*Параметры!$B$3,0),Q3)) | T3: Не дозвонились | U3: не дозвон | W3: =IF(T3="Оплачено",1,0) -> 0 | X3: =IF(OR(T3="Не дозвонились",Y3=0),0,1) -> 0 | Y3: 1
A4: 3 | B4: Андрей | C4: Андрей, стр. 6 | D4: 46174 | E4: =MONTH(D4) -> 6 | F4: Ана | G4: 60035437 | H4: кшн | I4: Входящий звонок | J4: тел. | K4: лоджия | L4: 46176 | M4: 1 | N4: 46177 | O4: 1 | P4: 24200 | Q4: 24200 | R4: MDL | S4: =IF(Q4="","",IF(R4="EUR",ROUND(Q4*Параметры!$B$3,0),Q4)) -> 24200 | T4: Думает | U4: перезвонить | W4: =IF(T4="Оплачено",1,0) -> 0 | X4: =IF(OR(T4="Не дозвонились",Y4=0),0,1) -> 1 | Y4: 1 | AB4: хочет скидку
A5: 4 | B5: Наталья | C5: Наталья, стр. 2 | D5: 46175 | E5: =MONTH(D5) -> 6 | F5: Бежан Ана | G5: 60058677 | H5: Кишинев | I5: Instagram | J5: инста | K5: Частный дом, все окна | L5: 46176 | M5: 1 | N5: 46176 | O5: 1 | P5: 128100 | Q5: 128100 | R5: MDL | S5: =IF(Q5="","",IF(R5="EUR",ROUND(Q5*Параметры!$B$3,0),Q5)) -> 128100 | T5: Отказ | U5: Отказ | W5: =IF(T5="Оплачено",1,0) -> 0 | X5: =IF(OR(T5="Не дозвонились",Y5=0),0,1) -> 1 | Y5: 1
A6: 5 | B6: Наталья | C6: Наталья, стр. 3 | D6: 46175 | E6: =MONTH(D6) -> 6 | F6: Ротару Ана | G6: 60039834 | H6: Кишинёв, Ботаника | I6: Instagram | J6: Instagram | K6: Окно двухстворчатое | L6: 46179 | M6: 1 | N6: 46180 | O6: 1 | P6: 9000 | Q6: 9000 | R6: MDL | S6: =IF(Q6="","",IF(R6="EUR",ROUND(Q6*Параметры!$B$3,0),Q6)) -> 9000 | T6: Думает | U6: Думает | W6: =IF(T6="Оплачено",1,0) -> 0 | X6: =IF(OR(T6="Не дозвонились",Y6=0),0,1) -> 1 | Y6: 1 | AB6: повторный клиент
A7: 6 | B7: Наталья | C7: Наталья, стр. 4 | D7: 46175 | E7: =MONTH(D7) -> 6 | F7: Шевченко Лариса | G7: 60029561 | H7: Кишинев | I7: 999.md | J7: 999.md | K7: Подоконники | M7: 0 | O7: 0 | S7: =IF(Q7="","",IF(R7="EUR",ROUND(Q7*Параметры!$B$3,0),Q7)) | T7: Отказ | U7: Отказ | W7: =IF(T7="Оплачено",1,0) -> 0 | X7: =IF(OR(T7="Не дозвонились",Y7=0),0,1) -> 1 | Y7: 1
A8: 7 | B8: Ион | C8: Ion, стр. 3 | D8: 46175 | E8: =MONTH(D8) -> 6 | F8: Mirabel Studio S.R.L. | G8: 22090758 | H8: Chisinau | I8: Входящий звонок | J8: apel | K8: depozit | M8: 0 | O8: 0 | S8: =IF(Q8="","",IF(R8="EUR",ROUND(Q8*Параметры!$B$3,0),Q8)) | T8: Не дозвонились | U8: nu răspunde | W8: =IF(T8="Оплачено",1,0) -> 0 | X8: =IF(OR(T8="Не дозвонились",Y8=0),0,1) -> 0 | Y8: 1
A9: 8 | B9: Ион | C9: Ion, стр. 4 | D9: 46175 | E9: =MONTH(D9) -> 6 | F9: Галина Кравченко | G9: 60034250 | H9: Chișinău, sec. Centru | I9: Facebook | J9: Facebook | K9: fereastră 2 canate | L9: 46180 | M9: 1 | N9: 46180 | O9: 1 | P9: 8 500 | Q9: 8500 | R9: MDL | S9: =IF(Q9="","",IF(R9="EUR",ROUND(Q9*Параметры!$B$3,0),Q9)) -> 8500 | T9: Думает | U9: se gândește | W9: =IF(T9="Оплачено",1,0) -> 0 | X9: =IF(OR(T9="Не дозвонились",Y9=0),0,1) -> 1 | Y9: 1 | AB9: нужен монтаж в субботу
A10: 9 | B10: Ион | C10: Ion, стр. 5 | D10: 46175 | E10: =MONTH(D10) -> 6 | F10: Galina Belova | G10: 60034817 | H10: Кишинев | I10: Instagram | J10: Instagram | K10: окна квартира | M10: 0 | O10: 0 | S10: =IF(Q10="","",IF(R10="EUR",ROUND(Q10*Параметры!$B$3,0),Q10)) | T10: Не дозвонились | U10: nu răspunde | W10: =IF(T10="Оплачено",1,0) -> 0 | X10: =IF(OR(T10="Не дозвонились",Y10=0),0,1) -> 0 | Y10: 1
A11: 10 | B11: Андрей | C11: Андрей, стр. 7 | D11: 46175 | E11: =MONTH(D11) -> 6 | F11: Игорь | G11: 60016889 | H11: КИШИНЕВ | I11: Instagram | J11: insta | K11: окна (квартира) | L11: 46176 | M11: 1 | N11: 46177 | O11: 1 | P11: 1830€ | Q11: 1830 | R11: EUR | S11: =IF(Q11="","",IF(R11="EUR",ROUND(Q11*Параметры!$B$3,0),Q11)) -> 36855 | T11: Думает | U11: думают | W11: =IF(T11="Оплачено",1,0) -> 0 | X11: =IF(OR(T11="Не дозвонились",Y11=0),0,1) -> 1 | Y11: 1 | AA11: евро: 1830€
A12: 11 | B12: Ион | C12: Ion, стр. 6 | D12: 46176 | E12: =MONTH(D12) -> 6 | F12: Elena Lupu | G12: 60064080 | H12: Balti | I12: 999.md | J12: 999 | K12: ferestre apartament | M12: 0 | O12: 0 | S12: =IF(Q12="","",IF(R12="EUR",ROUND(Q12*Параметры!$B$3,0),Q12)) | T12: Не дозвонились | U12: nu răspunde | W12: =IF(T12="Оплачено",1,0) -> 0 | X12: =IF(OR(T12="Не дозвонились",Y12=0),0,1) -> 0 | Y12: 1
A13: 12 | B13: Андрей | C13: Андрей, стр. 8 | D13: 46176 | E13: =MONTH(D13) -> 6 | F13: Оксана Белова | G13: 60017179 | H13: Ботаника | I13: 999.md | J13: с 999 | K13: балкон | M13: 0 | O13: 0 | S13: =IF(Q13="","",IF(R13="EUR",ROUND(Q13*Параметры!$B$3,0),Q13)) | T13: Пропал | U13: пропал | W13: =IF(T13="Оплачено",1,0) -> 0 | X13: =IF(OR(T13="Не дозвонились",Y13=0),0,1) -> 1 | Y13: 1
A14: 13 | B14: Наталья | C14: Наталья, стр. 5 | D14: 46177 | E14: =MONTH(D14) -> 6 | F14: Опря Кристина | G14: 60031982 | H14: Бельцы | I14: Рекомендация | J14: Рекомендация | K14: Остекление балкона | L14: 46179 | M14: 1 | N14: 46180 | O14: 1 | P14: 21200 | Q14: 21200 | R14: MDL | S14: =IF(Q14="","",IF(R14="EUR",ROUND(Q14*Параметры!$B$3,0),Q14)) -> 21200 | T14: Оплачено | U14: Оплачено | V14: 46182 | W14: =IF(T14="Оплачено",1,0) -> 1 | X14: =IF(OR(T14="Не дозвонились",Y14=0),0,1) -> 1 | Y14: 1
A15: 14 | B15: Наталья | C15: Наталья, стр. 6 | D15: 46177 | E15: =MONTH(D15) -> 6 | F15: Постолаки Дойна | G15: 60067775 | H15: Кишинёв | I15: Не указан | K15: Окна, квартира (3 шт) | M15: 0 | O15: 0 | S15: =IF(Q15="","",IF(R15="EUR",ROUND(Q15*Параметры!$B$3,0),Q15)) | T15: Не дозвонились | U15: Не дозвонилась | W15: =IF(T15="Оплачено",1,0) -> 0 | X15: =IF(OR(T15="Не дозвонились",Y15=0),0,1) -> 0 | Y15: 1
A16: 15 | B16: Ион | C16: Ion, стр. 7 | D16: 46177 | E16: =MONTH(D16) -> 6 | F16: Лариса Петренко | G16: 60083510 | H16: Кишинев | I16: Instagram | J16: Insta | K16: balcon | L16: 46181 | M16: 1 | N16: 46183 | O16: 1 | P16: 17 500 | Q16: 17500 | R16: MDL | S16: =IF(Q16="","",IF(R16="EUR",ROUND(Q16*Параметры!$B$3,0),Q16)) -> 17500 | T16: Отказ | U16: отказ | W16: =IF(T16="Оплачено",1,0) -> 0 | X16: =IF(OR(T16="Не дозвонились",Y16=0),0,1) -> 1 | Y16: 1 | AB16: передумал, sună după ora 18
A17: 16 | B17: Ион | C17: Ion, стр. 8 | D17: 46177 | E17: =MONTH(D17) -> 6 | F17: Alla Nichitina | G17: 60003804 | H17: Comrat | I17: Facebook | J17: FB | K17: fereastră | L17: 46182 | M17: 1 | O17: 0 | S17: =IF(Q17="","",IF(R17="EUR",ROUND(Q17*Параметры!$B$3,0),Q17)) | T17: Отказ | U17: отказ | W17: =IF(T17="Оплачено",1,0) -> 0 | X17: =IF(OR(T17="Не дозвонились",Y17=0),0,1) -> 1 | Y17: 1
A18: 17 | B18: Андрей | C18: Андрей, стр. 9 | D18: 46177 | E18: =MONTH(D18) -> 6 | F18: Александру | G18: 60017947 | H18: Кишинев | I18: Instagram | J18: insta | K18: частный дом | M18: 0 | O18: 0 | S18: =IF(Q18="","",IF(R18="EUR",ROUND(Q18*Параметры!$B$3,0),Q18)) | T18: Отказ | U18: отказ | W18: =IF(T18="Оплачено",1,0) -> 0 | X18: =IF(OR(T18="Не дозвонились",Y18=0),0,1) -> 1 | Y18: 1 | AB18: просто узнать цену
A19: 18 | B19: Андрей | C19: Андрей, стр. 10 | D19: 46177 | E19: =MONTH(D19) -> 6 | F19: Виктор | G19: 60074475 | H19: Орхей | I19: Входящий звонок | J19: звонила | K19: 3 окна + балкон | L19: 46178 | M19: 1 | N19: 46179 | O19: 1 | P19: 21500 | Q19: 21500 | R19: MDL | S19: =IF(Q19="","",IF(R19="EUR",ROUND(Q19*Параметры!$B$3,0),Q19)) -> 21500 | T19: Оплачено | U19: оплатили | V19: 46195 | W19: =IF(T19="Оплачено",1,0) -> 1 | X19: =IF(OR(T19="Не дозвонились",Y19=0),0,1) -> 1 | Y19: 1
A20: 19 | B20: Наталья | C20: Наталья, стр. 7 | D20: 46178 | E20: =MONTH(D20) -> 6 | F20: Сырбу Лилиана | G20: 60051829 | H20: Криково | I20: Facebook | J20: Facebook | K20: Частный дом, все окна | L20: 46184 | M20: 1 | N20: 46185 | O20: 1 | P20: 66900 | Q20: 66900 | R20: MDL | S20: =IF(Q20="","",IF(R20="EUR",ROUND(Q20*Параметры!$B$3,0),Q20)) -> 66900 | T20: Отказ | U20: Отказ | W20: =IF(T20="Оплачено",1,0) -> 0 | X20: =IF(OR(T20="Не дозвонились",Y20=0),0,1) -> 1 | Y20: 1 | AB20: дорого, повторный клиент
A21: 20 | B21: Наталья | C21: Наталья, стр. 8 | D21: 46178 | E21: =MONTH(D21) -> 6 | F21: Савченко Юрий | G21: 60030645 | H21: Кишинев (Рышкановка) | I21: Instagram | J21: Instagram | K21: Лоджия под ключ | M21: 0 | O21: 0 | S21: =IF(Q21="","",IF(R21="EUR",ROUND(Q21*Параметры!$B$3,0),Q21)) | T21: Отказ | U21: Отказ | W21: =IF(T21="Оплачено",1,0) -> 0 | X21: =IF(OR(T21="Не дозвонились",Y21=0),0,1) -> 1 | Y21: 1
A22: 21 | B22: Наталья | C22: Наталья, стр. 9 | D22: 46178 | E22: =MONTH(D22) -> 6 | F22: Негру Ана | G22: 60099600 | H22: Кишинев | I22: Рекомендация | J22: Рекомендация | K22: Окна в квартиру | L22: 46183 | M22: 1 | N22: 46184 | O22: 1 | P22: 39300 | Q22: 39300 | R22: MDL | S22: =IF(Q22="","",IF(R22="EUR",ROUND(Q22*Параметры!$B$3,0),Q22)) -> 39300 | T22: Отказ | U22: Отказ | W22: =IF(T22="Оплачено",1,0) -> 0 | X22: =IF(OR(T22="Не дозвонились",Y22=0),0,1) -> 1 | Y22: 1 | AB22: просил рассрочку
A23: 22 | B23: Наталья | C23: Наталья, стр. 10 | D23: 46178 | E23: =MONTH(D23) -> 6 | F23: Романов Дмитрий | G23: 60039627 | H23: Яловены | I23: Instagram | J23: Instagram | K23: Частный дом, все окна | M23: 0 | O23: 0 | S23: =IF(Q23="","",IF(R23="EUR",ROUND(Q23*Параметры!$B$3,0),Q23)) | T23: Отказ | U23: Отказ | W23: =IF(T23="Оплачено",1,0) -> 0 | X23: =IF(OR(T23="Не дозвонились",Y23=0),0,1) -> 1 | Y23: 1 | AB23: не наш регион
A24: 23 | B24: Андрей | C24: Андрей, стр. 11 | D24: 46178 | E24: =MONTH(D24) -> 6 | F24: Лилиана Р. | G24: 60018378 | H24: Каушаны | I24: Instagram | J24: инстаграм | K24: балкон тёплый | M24: 0 | O24: 0 | S24: =IF(Q24="","",IF(R24="EUR",ROUND(Q24*Параметры!$B$3,0),Q24)) | T24: Не дозвонились | U24: не дозвон | W24: =IF(T24="Оплачено",1,0) -> 0 | X24: =IF(OR(T24="Не дозвонились",Y24=0),0,1) -> 0 | Y24: 1
A25: 24 | B25: Андрей | C25: Андрей, стр. 12 | D25: 46178 | E25: =MONTH(D25) -> 6 | F25: Серджиу Т. | G25: 60033224 | H25: Бельцы | I25: Facebook | J25: Facebook реклама | K25: дом под ключ | M25: 0 | O25: 0 | S25: =IF(Q25="","",IF(R25="EUR",ROUND(Q25*Параметры!$B$3,0),Q25)) | T25: Пропал | U25: пропал | W25: =IF(T25="Оплачено",1,0) -> 0 | X25: =IF(OR(T25="Не дозвонились",Y25=0),0,1) -> 1 | Y25: 1
A26: 25 | B26: Андрей | C26: Андрей, стр. 14 | D26: 46178 | E26: =MONTH(D26) -> 6 | F26: Ольга Ткаченко | G26: 60096112 | H26: Ботаника | I26: 999.md | J26: 999 | K26: окна кв | M26: 0 | O26: 0 | S26: =IF(Q26="","",IF(R26="EUR",ROUND(Q26*Параметры!$B$3,0),Q26)) | T26: Отказ | U26: нет | W26: =IF(T26="Оплачено",1,0) -> 0 | X26: =IF(OR(T26="Не дозвонились",Y26=0),0,1) -> 1 | Y26: 1 | AB26: белые
A27: 26 | B27: Наталья | C27: Наталья, стр. 11 | D27: 46179 | E27: =MONTH(D27) -> 6 | F27: Лысенко Павел | G27: 60037529 | H27: Кишинев (Рышкановка) | I27: 999.md | J27: 999.md | K27: Окно двухстворчатое | M27: 0 | O27: 0 | S27: =IF(Q27="","",IF(R27="EUR",ROUND(Q27*Параметры!$B$3,0),Q27)) | T27: Отказ | U27: Отказ | W27: =IF(T27="Оплачено",1,0) -> 0 | X27: =IF(OR(T27="Не дозвонились",Y27=0),0,1) -> 1 | Y27: 1 | AB27: передумал, ламинация под дерево
A28: 27 | B28: Наталья | C28: Наталья, стр. 12 | D28: 46179 | E28: =MONTH(D28) -> 6 | F28: Ковальчук Геннадий | G28: 60003170 | H28: Орхей | I28: 999.md | J28: 999.md | K28: Москитные сетки | M28: 0 | O28: 0 | S28: =IF(Q28="","",IF(R28="EUR",ROUND(Q28*Параметры!$B$3,0),Q28)) | T28: Отказ | U28: Отказ | W28: =IF(T28="Оплачено",1,0) -> 0 | X28: =IF(OR(T28="Не дозвонились",Y28=0),0,1) -> 1 | Y28: 1 | AB28: передумал
A29: 28 | B29: Ион | C29: Ion, стр. 9 | D29: 46179 | E29: =MONTH(D29) -> 6 | F29: Victor Postolachi | G29: 60070361 | H29: Chisinau | I29: Instagram | J29: Instagram | K29: balcon + izolare | M29: 0 | O29: 0 | S29: =IF(Q29="","",IF(R29="EUR",ROUND(Q29*Параметры!$B$3,0),Q29)) | T29: Не дозвонились | U29: nu răspunde | W29: =IF(T29="Оплачено",1,0) -> 0 | X29: =IF(OR(T29="Не дозвонились",Y29=0),0,1) -> 0 | Y29: 1
A30: 29 | B30: Андрей | C30: Андрей, стр. 13 | D30: 46179 | E30: =MONTH(D30) -> 6 | F30: Алла | G30: 60093459 | H30: Kишинёв | I30: Facebook | J30: фейсбук | K30: балкон тёплый | L30: 46185 | M30: 1 | N30: 46194 | O30: 1 | P30: 20700 | Q30: 20700 | R30: MDL | S30: =IF(Q30="","",IF(R30="EUR",ROUND(Q30*Параметры!$B$3,0),Q30)) -> 20700 | T30: Отказ | U30: нет | W30: =IF(T30="Оплачено",1,0) -> 0 | X30: =IF(OR(T30="Не дозвонились",Y30=0),0,1) -> 1 | Y30: 1 | AB30: не берёт трубку, sună după ora 18
A31: 30 | B31: Наталья | C31: Наталья, стр. 13 | D31: 46180 | E31: =MONTH(D31) -> 6 | F31: Гончаренко Галина | G31: 60095963 | H31: Кишинев | I31: 999.md | J31: 999.md | K31: Окна в квартиру | M31: 0 | O31: 0 | S31: =IF(Q31="","",IF(R31="EUR",ROUND(Q31*Параметры!$B$3,0),Q31)) | T31: Отказ | U31: Отказ | W31: =IF(T31="Оплачено",1,0) -> 0 | X31: =IF(OR(T31="Не дозвонились",Y31=0),0,1) -> 1 | Y31: 1
A32: 31 | B32: Наталья | C32: Наталья, стр. 14 | D32: 46180 | E32: =MONTH(D32) -> 6 | F32: Райлян Татьяна | G32: 60057107 | H32: Кишинев (Рышкановка) | I32: Рекомендация | J32: По рекомендации | K32: Окно двухстворчатое | L32: 46182 | M32: 1 | O32: 0 | S32: =IF(Q32="","",IF(R32="EUR",ROUND(Q32*Параметры!$B$3,0),Q32)) | T32: Отказ | U32: Отказ | W32: =IF(T32="Оплачено",1,0) -> 0 | X32: =IF(OR(T32="Не дозвонились",Y32=0),0,1) -> 1 | Y32: 1 | AB32: дорого, жена решает
A33: 32 | B33: Наталья | C33: Наталья, стр. 15 | D33: 46181 | E33: =MONTH(D33) -> 6 | F33: Гросу Виктор | G33: 60096490 | H33: Кишинев (Рышкановка) | I33: Instagram | J33: инста | K33: Лоджия под ключ | L33: 46184 | M33: 1 | O33: 0 | S33: =IF(Q33="","",IF(R33="EUR",ROUND(Q33*Параметры!$B$3,0),Q33)) | T33: Отказ | U33: Отказ | W33: =IF(T33="Оплачено",1,0) -> 0 | X33: =IF(OR(T33="Не дозвонились",Y33=0),0,1) -> 1 | Y33: 1 | AB33: дорого
A34: 33 | B34: Наталья | C34: Наталья, стр. 16 | D34: 46181 | E34: =MONTH(D34) -> 6 | F34: Фёдорова Ольга | G34: 60020673 | H34: Кишинёв | I34: Рекомендация | J34: По рекомендации | K34: Остекление балкона | L34: 46185 | M34: 1 | N34: 46185 | O34: 1 | P34: 32 400 лей | Q34: 32400 | R34: MDL | S34: =IF(Q34="","",IF(R34="EUR",ROUND(Q34*Параметры!$B$3,0),Q34)) -> 32400 | T34: Оплачено | U34: Оплачено | V34: 46199 | W34: =IF(T34="Оплачено",1,0) -> 1 | X34: =IF(OR(T34="Не дозвонились",Y34=0),0,1) -> 1 | Y34: 1 | AB34: повторный клиент
A35: 34 | B35: Ион | C35: Ion, стр. 10 | D35: 46181 | E35: =MONTH(D35) -> 6 | F35: Ирина Кравченко | G35: 60084046 | H35: Chișinău | I35: 999.md | J35: 999 | K35: casă - toate geamurile | L35: 46186 | M35: 1 | N35: 46192 | O35: 1 | P35: 4170 EUR | Q35: 4170 | R35: EUR | S35: =IF(Q35="","",IF(R35="EUR",ROUND(Q35*Параметры!$B$3,0),Q35)) -> 83982 | T35: Думает | U35: se gândește | W35: =IF(T35="Оплачено",1,0) -> 0 | X35: =IF(OR(T35="Не дозвонились",Y35=0),0,1) -> 1 | Y35: 1 | AA35: евро: 4170 EUR
A36: 35 | B36: Андрей | C36: Андрей, стр. 15 | D36: 46181 | E36: =MONTH(D36) -> 6 | F36: Светлана | G36: 60076702 | H36: Каушаны | I36: Instagram | J36: Instagram | K36: окна кв | M36: 0 | O36: 0 | S36: =IF(Q36="","",IF(R36="EUR",ROUND(Q36*Параметры!$B$3,0),Q36)) | T36: Отказ | U36: нет | W36: =IF(T36="Оплачено",1,0) -> 0 | X36: =IF(OR(T36="Не дозвонились",Y36=0),0,1) -> 1 | Y36: 1 | AB36: передумал
A37: 36 | B37: Андрей | C37: Андрей, стр. 16 | D37: 46181 | E37: =MONTH(D37) -> 6 | F37: Ана (Чеканы) | H37: Ботаника | I37: 999.md | J37: объявление 999 | K37: окно 2ств | M37: 0 | O37: 0 | S37: =IF(Q37="","",IF(R37="EUR",ROUND(Q37*Параметры!$B$3,0),Q37)) | T37: Пропал | U37: пропал | W37: =IF(T37="Оплачено",1,0) -> 0 | X37: =IF(OR(T37="Не дозвонились",Y37=0),0,1) -> 1 | Y37: 1 | AB37: просто узнать цену
A38: 37 | B38: Андрей | C38: Андрей, стр. 17 | D38: 46182 | E38: =MONTH(D38) -> 6 | F38: Аурелия | G38: 60004640 | H38: Kишинёв | I38: Входящий звонок | J38: звонила | K38: 1 окно кухня | M38: 0 | O38: 0 | S38: =IF(Q38="","",IF(R38="EUR",ROUND(Q38*Параметры!$B$3,0),Q38)) | T38: Не дозвонились | U38: не дозвон | W38: =IF(T38="Оплачено",1,0) -> 0 | X38: =IF(OR(T38="Не дозвонились",Y38=0),0,1) -> 0 | Y38: 1 | AB38: жена решает
A39: 38 | B39: Наталья | C39: Наталья, стр. 17 | D39: 46183 | E39: =MONTH(D39) -> 6 | F39: Попов Игорь | G39: 60077793 | H39: Дурлешты | I39: Facebook | J39: Facebook | K39: Входная дверь ПВХ | M39: 0 | O39: 0 | S39: =IF(Q39="","",IF(R39="EUR",ROUND(Q39*Параметры!$B$3,0),Q39)) | T39: Отказ | U39: Отказ | W39: =IF(T39="Оплачено",1,0) -> 0 | X39: =IF(OR(T39="Не дозвонились",Y39=0),0,1) -> 1 | Y39: 1
A40: 39 | B40: Наталья | C40: Наталья, стр. 18 | D40: 46183 | E40: =MONTH(D40) -> 6 | F40: Мельник Вероника | G40: 60059840 | H40: Кишинёв | I40: Instagram | J40: Instagram | K40: Окна, квартира (3 шт) | M40: 0 | O40: 0 | S40: =IF(Q40="","",IF(R40="EUR",ROUND(Q40*Параметры!$B$3,0),Q40)) | T40: Не дозвонились | U40: Не дозвонилась | W40: =IF(T40="Оплачено",1,0) -> 0 | X40: =IF(OR(T40="Не дозвонились",Y40=0),0,1) -> 0 | Y40: 1
...

Sheet Качество данных
A1: Что было не так в исходном файле и как это исправлено
A3: Три листа в разном формате | B3: У Иона другой порядок колонок и румынские названия, у Андрея имя и телефон в одной ячейке, заголовок и разбивка по месяцам внутри листа. Всё сведено в единый формат на листе «Сводная».
A4: Даты в 10+ форматах | B4: ДД.ММ.ГГГГ, М/Д/ГГ (у Иона американский формат), «4 июн», «1.6», ГГГГ-ММ-ДД, числа Excel. Все приведены к датам.
A5: «вчера» вместо даты | B5: Две строки у Андрея. Поставлена дата предыдущей строки — точная дата неизвестна (отмечено в «Замечаниях»).
A6: Суммы текстом | B6: «32 400 лей», «39.400 lei», «27100,00», «~19к», «22900 + монтаж 2500». Приблизительные взяты как есть, монтаж включён в сумму. Одна сумма «уточнить» — пустая.
A7: Суммы в евро | B7: 6 сделок в EUR — пересчитаны по курсу на листе «Параметры».
A8: Статусы на трёх языках | B8: 30 разных написаний сведены к 7 статусам (см. «Параметры»). «да»/«+» у Андрея — это оплата.
A9: Точные дубли строк: 8 | B9: Одна и та же строка вписана дважды (у всех трёх менеджеров). Исключены из воронки.
A10: Один клиент у двух менеджеров: 12 | B10: Передачи («передала Андрею») и повторные обращения («дубль?», «dublu?»). Сопоставлены по телефону; в воронке учтена самая продвинутая запись.
A11: Ошибка в «Своде Марина» | B11: Андрей, июнь: в своде 51 700, по данным 57 100 (3 оплаты: 21 500 + 11 000 + 24 600) — похоже на перестановку цифр. Наталья и Ион сходятся.
A12: «Итого» у Андрея не сходятся | B12: Итого июнь 655 037 (евро пересчитано по другому курсу), итого август 501 700 при 474 000 по строкам — видимо, с учётом дубля. Эти итоги — сумма всех КП, а не оплат.
A13: Клиенты без телефона | B13: У Андрея часть клиентов записана без номера («Ана (Чеканы)») — их нельзя проверить на дубли.
A16: Исключённые строки
A17: Менеджер | B17: Строка | C17: Клиент | D17: Статус | E17: Причина
A18: Наталья | B18: 31 | C18: SRL «Pomul Prim» | D18: Передала Андрею | E18: Тот же клиент (тел. 22057441), что у Андрей, стр. 27 — в воронке учтена та запись
A19: Ион | B19: 34 | C19: Sergiu Stratan | D19: dublu? | E19: Тот же клиент (тел. 60035505), что у Наталья, стр. 29 — в воронке учтена та запись
A20: Наталья | B20: 54 | C20: Фёдорова Лариса | D20: Не дозвонилась | E20: Тот же клиент (тел. 60048052), что у Андрей, стр. 52 — в воронке учтена та запись
A21: Ион | B21: 49 | C21: Оксана Волкова | D21: отказ | E21: Точная копия строки 47 на листе Ион
A22: Андрей | B22: 48 | C22: Олег Ш. | D22: пропал | E22: Точная копия строки 47 на листе Андрей
A23: Ион | B23: 51 | C23: Галина Фёдорова | D23: nu răspunde | E23: Тот же клиент (тел. 60092898), что у Андрей, стр. 44 — в воронке учтена та запись
A24: Андрей | B24: 73 | C24: Людмила Ф. | D24: пропал | E24: Точная копия строки 71 на листе Андрей
A25: Наталья | B25: 80 | C25: Бежан Аурелия | D25: Отказ | E25: Точная копия строки 78 на листе Наталья
A26: Андрей | B26: 75 | C26: Лилиана Г. | D26: дубль? | E26: Тот же клиент (тел. 60066411), что у Наталья, стр. 81 — в воронке учтена та запись
A27: Ион | B27: 77 | C27: Ion Popescu | D27: передал Наталье | E27: Тот же клиент (тел. 60079273), что у Наталья, стр. 91 — в воронке учтена та запись
A28: Наталья | B28: 95 | C28: Кузнецов Виталий | D28: Отказ | E28: Точная копия строки 94 на листе Наталья
A29: Андрей | B29: 100 | C29: Ирина Морозова | D29: дубль? | E29: Тот же клиент (тел. 60010823), что у Ион, стр. 94 — в воронке учтена та запись
... A37: Наталья | B37: 154 | C37: Ботнарь Николае | D37: Отказ | E37: Точная копия строки 153 на листе Наталья

Sheet Параметры
A1: Параметры расчёта
A3: Курс EUR → MDL | B3: 20.1396 | C3: Официальный курс НБМ на 06.07.2026 (cursvalutarazi.md / bnm.md). Можно поменять — суммы в евро пересчитаются.
A5: Как читать статусы (приведены к единому виду)
A6: Оплачено | B6: Оплачено, achitat, achitat ✓, оплатили, опл; у Андрея также «да» и «+» (зелёные строки с датой/отметкой оплаты)
A7: Договор | B7: Договор подписан, оплаты ещё нет
A8: Думает | B8: Думает, думают, se gândește, перезвонить
A9: Отказ | B9: Отказ, refuz, нет
A10: Пропал | B10: Только у Андрея: клиент перестал выходить на связь. Считается как состоявшийся контакт
A11: Не дозвонились | B11: Не дозвонилась, nu răspunde, не дозвон
A12: Передан / Дубль? | B12: Передан другому менеджеру или помечен как дубль — такие строки исключены из воронки, клиент учтён один раз
A14: Этапы воронки
A15: Лид | B15: Уникальный клиент (дубли по телефону схлопнуты)
A16: Контакт | B16: Дозвонились: статус не «Не дозвонились»
A17: Замер | B17: Есть дата замера или отметка «да»
A18: КП | B18: Отправлено коммерческое предложение (есть дата КП)
A19: Оплата | B19: Статус «Оплачено»
